Workbook

Sheet Índice
A1: Bonos y TIR · 50 ejercicios prácticos
A2: Resolvé en la hoja «Ejercicios». Acá ves el avance; las respuestas están en «Soluciones» y el resumen de funciones en «Fórmulas».
A4: Correctos | B4: =COUNTIF(C9:C58,"✔*") -> 0
A5: Respondidos | B5: =COUNTIF(C9:C58,"✔*")+COUNTIF(C9:C58,"✘*") -> 0
A6: Acierto | B6: =IF(B5=0,"",B4/B5)
A8: Ej. | B8: Tema | C8: Estado | D8: Ir
A9: 1 | B9: Cupón cero · precio | C9: =IF(Ejercicios!D10="","Pendiente",Ejercicios!D10) -> Pendiente | D9: =HYPERLINK("#Ejercicios!A10","Ir al ej. 1") -> Ir al ej. 1
A10: 2 | B10: Cupón cero · precio | C10: =IF(Ejercicios!D17="","Pendiente",Ejercicios!D17) -> Pendiente | D10: =HYPERLINK("#Ejercicios!A17","Ir al ej. 2") -> Ir al ej. 2
A11: 3 | B11: Cupón cero · precio | C11: =IF(Ejercicios!D24="","Pendiente",Ejercicios!D24) -> Pendiente | D11: =HYPERLINK("#Ejercicios!A24","Ir al ej. 3") -> Ir al ej. 3
A12: 4 | B12: Letra · precio con TNA | C12: =IF(Ejercicios!D31="","Pendiente",Ejercicios!D31) -> Pendiente | D12: =HYPERLINK("#Ejercicios!A31","Ir al ej. 4") -> Ir al ej. 4
A13: 5 | B13: Cupón cero · precio | C13: =IF(Ejercicios!D38="","Pendiente",Ejercicios!D38) -> Pendiente | D13: =HYPERLINK("#Ejercicios!A38","Ir al ej. 5") -> Ir al ej. 5
A14: 6 | B14: Cupón cero · TIR | C14: =IF(Ejercicios!D45="","Pendiente",Ejercicios!D45) -> Pendiente | D14: =HYPERLINK("#Ejercicios!A45","Ir al ej. 6") -> Ir al ej. 6
A15: 7 | B15: Letra · TEA | C15: =IF(Ejercicios!D52="","Pendiente",Ejercicios!D52) -> Pendiente | D15: =HYPERLINK("#Ejercicios!A52","Ir al ej. 7") -> Ir al ej. 7
A16: 8 | B16: Letra · TNA | C16: =IF(Ejercicios!D59="","Pendiente",Ejercicios!D59) -> Pendiente | D16: =HYPERLINK("#Ejercicios!A59","Ir al ej. 8") -> Ir al ej. 8
A17: 9 | B17: Cupón cero · TIR | C17: =IF(Ejercicios!D66="","Pendiente",Ejercicios!D66) -> Pendiente | D17: =HYPERLINK("#Ejercicios!A66","Ir al ej. 9") -> Ir al ej. 9
A18: 10 | B18: Bullet · precio | C18: =IF(Ejercicios!D74="","Pendiente",Ejercicios!D74) -> Pendiente | D18: =HYPERLINK("#Ejercicios!A74","Ir al ej. 10") -> Ir al ej. 10
A19: 11 | B19: Bullet · precio | C19: =IF(Ejercicios!D82="","Pendiente",Ejercicios!D82) -> Pendiente | D19: =HYPERLINK("#Ejercicios!A82","Ir al ej. 11") -> Ir al ej. 11
A20: 12 | B20: Bullet · precio | C20: =IF(Ejercicios!D90="","Pendiente",Ejercicios!D90) -> Pendiente | D20: =HYPERLINK("#Ejercicios!A90","Ir al ej. 12") -> Ir al ej. 12
A21: 13 | B21: Bullet · precio | C21: =IF(Ejercicios!D98="","Pendiente",Ejercicios!D98) -> Pendiente | D21: =HYPERLINK("#Ejercicios!A98","Ir al ej. 13") -> Ir al ej. 13
A22: 14 | B22: Bullet semestral · precio | C22: =IF(Ejercicios!D106="","Pendiente",Ejercicios!D106) -> Pendiente | D22: =HYPERLINK("#Ejercicios!A106","Ir al ej. 14") -> Ir al ej. 14
A23: 15 | B23: Bullet semestral · precio | C23: =IF(Ejercicios!D114="","Pendiente",Ejercicios!D114) -> Pendiente | D23: =HYPERLINK("#Ejercicios!A114","Ir al ej. 15") -> Ir al ej. 15
A24: 16 | B24: Bullet · TIR | C24: =IF(Ejercicios!D122="","Pendiente",Ejercicios!D122) -> Pendiente | D24: =HYPERLINK("#Ejercicios!A122","Ir al ej. 16") -> Ir al ej. 16
A25: 17 | B25: Bullet · TIR | C25: =IF(Ejercicios!D130="","Pendiente",Ejercicios!D130) -> Pendiente | D25: =HYPERLINK("#Ejercicios!A130","Ir al ej. 17") -> Ir al ej. 17
A26: 18 | B26: Bullet · TIR | C26: =IF(Ejercicios!D138="","Pendiente",Ejercicios!D138) -> Pendiente | D26: =HYPERLINK("#Ejercicios!A138","Ir al ej. 18") -> Ir al ej. 18
A27: 19 | B27: Flujo irregular · TIR | C27: =IF(Ejercicios!D144="","Pendiente",Ejercicios!D144) -> Pendiente | D27: =HYPERLINK("#Ejercicios!A144","Ir al ej. 19") -> Ir al ej. 19
A28: 20 | B28: Bullet · TIR | C28: =IF(Ejercicios!D152="","Pendiente",Ejercicios!D152) -> Pendiente | D28: =HYPERLINK("#Ejercicios!A152","Ir al ej. 20") -> Ir al ej. 20
A29: 21 | B29: Rendimiento del período | C29: =IF(Ejercicios!D159="","Pendiente",Ejercicios!D159) -> Pendiente | D29: =HYPERLINK("#Ejercicios!A159","Ir al ej. 21") -> Ir al ej. 21
A30: 22 | B30: Semestral · TIR del período | C30: =IF(Ejercicios!D167="","Pendiente",Ejercicios!D167) -> Pendiente | D30: =HYPERLINK("#Ejercicios!A167","Ir al ej. 22") -> Ir al ej. 22
A31: 23 | B31: Semestral · TEA | C31: =IF(Ejercicios!D175="","Pendiente",Ejercicios!D175) -> Pendiente | D31: =HYPERLINK("#Ejercicios!A175","Ir al ej. 23") -> Ir al ej. 23
A32: 24 | B32: Semestral · TNA | C32: =IF(Ejercicios!D183="","Pendiente",Ejercicios!D183) -> Pendiente | D32: =HYPERLINK("#Ejercicios!A183","Ir al ej. 24") -> Ir al ej. 24
A33: 25 | B33: Trimestral · TEA | C33: =IF(Ejercicios!D191="","Pendiente",Ejercicios!D191) -> Pendiente | D33: =HYPERLINK("#Ejercicios!A191","Ir al ej. 25") -> Ir al ej. 25
A34: 26 | B34: Amortizable · precio | C34: =IF(Ejercicios!D198="","Pendiente",Ejercicios!D198) -> Pendiente | D34: =HYPERLINK("#Ejercicios!A198","Ir al ej. 26") -> Ir al ej. 26
A35: 27 | B35: Amortizable · TIR | C35: =IF(Ejercicios!D204="","Pendiente",Ejercicios!D204) -> Pendiente | D35: =HYPERLINK("#Ejercicios!A204","Ir al ej. 27") -> Ir al ej. 27
A36: 28 | B36: Amortizable semestral · precio | C36: =IF(Ejercicios!D211="","Pendiente",Ejercicios!D211) -> Pendiente | D36: =HYPERLINK("#Ejercicios!A211","Ir al ej. 28") -> Ir al ej. 28
A37: 29 | B37: Amortizable semestral · TEA | C37: =IF(Ejercicios!D217="","Pendiente",Ejercicios!D217) -> Pendiente | D37: =HYPERLINK("#Ejercicios!A217","Ir al ej. 29") -> Ir al ej. 29
A38: 30 | B38: Amortizable con gracia · TIR | C38: =IF(Ejercicios!D223="","Pendiente",Ejercicios!D223) -> Pendiente | D38: =HYPERLINK("#Ejercicios!A223","Ir al ej. 30") -> Ir al ej. 30
A39: 31 | B39: Current yield | C39: =IF(Ejercicios!D229="","Pendiente",Ejercicios!D229) -> Pendiente | D39: =HYPERLINK("#Ejercicios!A229","Ir al ej. 31") -> Ir al ej. 31
A40: 32 | B40: Current yield | C40: =IF(Ejercicios!D237="","Pendiente",Ejercicios!D237) -> Pendiente | D40: =HYPERLINK("#Ejercicios!A237","Ir al ej. 32") -> Ir al ej. 32
A41: 33 | B41: Current yield | C41: =IF(Ejercicios!D243="","Pendiente",Ejercicios!D243) -> Pendiente | D41: =HYPERLINK("#Ejercicios!A243","Ir al ej. 33") -> Ir al ej. 33
A42: 34 | B42: Duration Macaulay | C42: =IF(Ejercicios!D250="","Pendiente",Ejercicios!D250) -> Pendiente | D42: =HYPERLINK("#Ejercicios!A250","Ir al ej. 34") -> Ir al ej. 34
...

Sheet Ejercicios
A1: 50 ejercicios de bonos y TIR para resolver con Excel
A2: Resolvé cada ejercicio en el espacio libre de la derecha o abajo, con las funciones de Excel. Cargá tu resultado en la celda amarilla «Tu respuesta»: la columna de al lado te dice si está bien. Los datos en azul son los del enunciado. Tasas y rendimientos se cargan como porcentaje (por ejemplo 7,72%), precios y durations como número (por ejemplo 92,42). Se acepta una diferencia chica por redondeo.
A3: Ejemplo de carga: | B3: 0.0772 | C3: ← así se ve una TIR de 7,72% bien cargada
A5: Ejercicio 1 | B5: Cupón cero · precio
A6: Un bono cupón cero de VN 100 vence dentro de 5 años. Si la TIR (tasa efectiva anual) de mercado es 10%, ¿cuál es su precio hoy?
A7: Valor nominal | B7: 100
A8: Años al vencimiento | B8: 5
A9: TIR efectiva anual | B9: 0.1
A10: Tu respuesta | D10: =IF(B10="","",IF(ABS(B10-Soluciones!$C$4)<=MAX(0.003*ABS(Soluciones!$C$4),0.0001),"✔ Correcto","✘ Revisá"))
A12: Ejercicio 2 | B12: Cupón cero · precio
A13: Bono cupón cero VN 1.000, vence en 3 años. TIR efectiva anual 8%. Calculá el precio.
A14: Valor nominal | B14: 1000
A15: Años | B15: 3
A16: TIR | B16: 0.08
A17: Tu respuesta | D17: =IF(B17="","",IF(ABS(B17-Soluciones!$C$5)<=MAX(0.003*ABS(Soluciones!$C$5),0.0001),"✔ Correcto","✘ Revisá"))
A19: Ejercicio 3 | B19: Cupón cero · precio
A20: Un cupón cero de VN 100 vence en 180 días. La TIR efectiva anual exigida es 45%. ¿Cuál es el precio? (base 365 días)
A21: Valor nominal | B21: 100
A22: Días al vencimiento | B22: 180
A23: TIR efectiva anual (TEA) | B23: 0.45
A24: Tu respuesta | D24: =IF(B24="","",IF(ABS(B24-Soluciones!$C$6)<=MAX(0.003*ABS(Soluciones!$C$6),0.0001),"✔ Correcto","✘ Revisá"))
A26: Ejercicio 4 | B26: Letra · precio con TNA
A27: Una letra VN 1.000 vence en 90 días y se negocia a una TNA de 36% (descuento racional, interés simple, base 365). ¿Precio?
A28: Valor nominal | B28: 1000
A29: Días | B29: 90
A30: TNA | B30: 0.36
A31: Tu respuesta | D31: =IF(B31="","",IF(ABS(B31-Soluciones!$C$7)<=MAX(0.003*ABS(Soluciones!$C$7),0.0001),"✔ Correcto","✘ Revisá"))
A33: Ejercicio 5 | B33: Cupón cero · precio
A34: Cupón cero VN 100 a 2 años. La tasa de mercado es 10% TNA con capitalización semestral (5% por semestre). ¿Precio?
A35: Valor nominal | B35: 100
A36: Semestres | B36: 4
A37: Tasa semestral | B37: 0.05
A38: Tu respuesta | D38: =IF(B38="","",IF(ABS(B38-Soluciones!$C$8)<=MAX(0.003*ABS(Soluciones!$C$8),0.0001),"✔ Correcto","✘ Revisá"))
A40: Ejercicio 6 | B40: Cupón cero · TIR
A41: Comprás a $80 un cupón cero de VN 100 que vence en 3 años. ¿Qué TIR efectiva anual obtenés?
A42: Precio | B42: 80
A43: Valor nominal | B43: 100
A44: Años | B44: 3
A45: Tu respuesta | D45: =IF(B45="","",IF(ABS(B45-Soluciones!$C$9)<=MAX(0.003*ABS(Soluciones!$C$9),0.0001),"✔ Correcto","✘ Revisá"))
A47: Ejercicio 7 | B47: Letra · TEA
...

Sheet Soluciones
A1: Soluciones (mirá solo después de intentarlo)
A3: Ej. | B3: Tema | C3: Respuesta | D3: Fórmula en Excel en español | E3: Cómo se resuelve
A4: 1 | B4: Cupón cero · precio | C4: =PV(Ejercicios!$B$9,Ejercicios!$B$8,0,-Ejercicios!$B$7) -> 62.092132 | D4: =VA(10%;5;0;-100) ó =100/(1+10%)^5 | E4: Se descuenta el único pago (100) 5 años a la TIR.
A5: 2 | B5: Cupón cero · precio | C5: =PV(Ejercicios!$B$16,Ejercicios!$B$15,0,-Ejercicios!$B$14) -> 793.83224 | D5: =VA(8%;3;0;-1000) | E5: 1.000 / 1,08^3.
A6: 3 | B6: Cupón cero · precio | C6: =Ejercicios!$B$21/(1+Ejercicios!$B$23)^(Ejercicios!$B$22/365) -> 83.257096 | D6: =100/(1+45%)^(180/365) | E6: Con tasa efectiva anual, el exponente es la fracción de año: días/365.
A7: 4 | B7: Letra · precio con TNA | C7: =Ejercicios!$B$28/(1+Ejercicios!$B$30*Ejercicios!$B$29/365) -> 918.47006 | D7: =1000/(1+36%*90/365) | E7: Con TNA (interés simple), el factor es 1 + TNA × días/365.
A8: 5 | B8: Cupón cero · precio | C8: =PV(Ejercicios!$B$37,Ejercicios!$B$36,0,-Ejercicios!$B$35) -> 82.270247 | D8: =VA(5%;4;0;-100) | E8: Se trabaja en semestres: 4 períodos al 5%.
A9: 6 | B9: Cupón cero · TIR | C9: =RATE(Ejercicios!$B$44,0,-Ejercicios!$B$42,Ejercicios!$B$43) -> 0.077217345 | D9: =TASA(3;0;-80;100) ó =(100/80)^(1/3)-1 | E9: TIR = (VN/precio)^(1/n) − 1.
A10: 7 | B10: Letra · TEA | C10: =(Ejercicios!$B$50/Ejercicios!$B$49)^(365/Ejercicios!$B$51)-1 -> 0.16884619 | D10: =(1000/950)^(365/120)-1 | E10: Se anualiza en forma compuesta: (VN/P)^(365/días) − 1.
A11: 8 | B11: Letra · TNA | C11: =(Ejercicios!$B$57/Ejercicios!$B$56-1)*365/Ejercicios!$B$58 -> 0.16008772 | D11: =(1000/950-1)*365/120 | E11: TNA = rendimiento del período × 365/días (sin capitalizar).
A12: 9 | B12: Cupón cero · TIR | C12: =RATE(Ejercicios!$B$65,0,-Ejercicios!$B$63,Ejercicios!$B$64) -> 0.095999333 | D12: =TASA(10;0;-399,85;1000) | E12: Es la inversa del ejercicio del banco: da 9,6%.
A13: 10 | B13: Bullet · precio | C13: =PV(Ejercicios!$B$73,Ejercicios!$B$72,-Ejercicios!$B$70*Ejercicios!$B$71,-Ejercicios!$B$70) -> 92.418426 | D13: =VA(10%;5;-8;-100) | E13: Cupón (8) como pago periódico y VN (100) como valor final. TIR > cupón → bajo la par.
A14: 11 | B14: Bullet · precio | C14: =PV(Ejercicios!$B$81,Ejercicios!$B$80,-Ejercicios!$B$79,-Ejercicios!$B$78) -> 939.25301 | D14: =VA(12%;4;-100;-1000) | E14: Lo vas a necesitar para el current yield del ejercicio 32.
A15: 12 | B15: Bullet · precio | C15: =PV(Ejercicios!$B$89,Ejercicios!$B$88,-Ejercicios!$B$86*Ejercicios!$B$87,-Ejercicios!$B$86) -> 100 | D15: =VA(6%;3;-6;-100) | E15: Si cupón = TIR, el bono vale la par.
A16: 13 | B16: Bullet · precio | C16: =PV(Ejercicios!$B$97,Ejercicios!$B$96,-Ejercicios!$B$94*Ejercicios!$B$95,-Ejercicios!$B$94) -> 115.09886 | D16: =VA(9%;7;-12;-100) | E16: Cupón > TIR → sobre la par.
A17: 14 | B17: Bullet semestral · precio | C17: =PV(Ejercicios!$B$105,Ejercicios!$B$104,-Ejercicios!$B$103,-Ejercicios!$B$102) -> 95.944552 | D17: =VA(4%;10;-3,5;-100) | E17: Todo en semestres: 10 períodos, cupón 3,5 y tasa del semestre.
A18: 15 | B18: Bullet semestral · precio | C18: =PV((1+Ejercicios!$B$113)^(1/2)-1,Ejercicios!$B$112,-Ejercicios!$B$110*Ejercicios!$B$111/2,-Ejercicios!$B$110) -> 980.5936 | D18: =VA((1+10%)^(1/2)-1;6;-45;-1000) | E18: Tasa semestral equivalente = 1,10^0,5 − 1 ≈ 4,88%. Cupón semestral = 1.000 × 9% / 2 = 45.
A19: 16 | B19: Bullet · TIR | C19: =RATE(Ejercicios!$B$121,Ejercicios!$B$120,-Ejercicios!$B$118,Ejercicios!$B$119) -> 0.085273628 | D19: =TASA(4;7;-95;100) ó =TIR(flujo -95;7;7;7;107) | E19: Bajo la par → TIR mayor que el cupón.
A20: 17 | B20: Bullet · TIR | C20: =RATE(Ejercicios!$B$129,Ejercicios!$B$128,-Ejercicios!$B$126,Ejercicios!$B$127) -> 0.087237388 | D20: =TASA(5;10;-105;100) | E20: Sobre la par → TIR menor que el cupón.
A21: 18 | B21: Bullet · TIR | C21: =RATE(Ejercicios!$B$137,Ejercicios!$B$136,-Ejercicios!$B$134,Ejercicios!$B$135) -> 0.08 | D21: =TASA(6;80;-1000;1000) | E21: A la par, TIR = tasa de cupón.
A22: 19 | B22: Flujo irregular · TIR | C22: =IRR(Ejercicios!$B$143:$F$143) -> 0.091575551 | D22: =TIR(B?:F?) (seleccioná la fila de flujos) | E22: La función TIR toma el flujo completo, con el precio negativo en el período 0.
A23: 20 | B23: Bullet · TIR | C23: =RATE(Ejercicios!$B$151,Ejercicios!$B$150,-Ejercicios!$B$148,Ejercicios!$B$149) -> 0.075613396 | D23: =TASA(6;5;-88;100) | E23: Precio bajo la par: la TIR queda por encima del 5%.
A24: 21 | B24: Rendimiento del período | C24: =(Ejercicios!$B$157+Ejercicios!$B$158)/Ejercicios!$B$156-1 -> 0.082474227 | D24: =(6+99)/97-1 | E24: Rendimiento = (cupón + precio de venta) / precio de compra − 1.
A25: 22 | B25: Semestral · TIR del período | C25: =RATE(Ejercicios!$B$166,Ejercicios!$B$165,-Ejercicios!$B$163,Ejercicios!$B$164) -> 0.047825993 | D25: =TASA(6;4;-96;100) | E25: La TASA devuelve la tasa del período de los flujos: acá, semestral.
A26: 23 | B26: Semestral · TEA | C26: =(1+RATE(Ejercicios!$B$174,Ejercicios!$B$173,-Ejercicios!$B$171,Ejercicios!$B$172))^2-1 -> 0.097939312 | D26: =(1+TASA(6;4;-96;100))^2-1 | E26: TEA = (1 + i semestral)^2 − 1.
A27: 24 | B27: Semestral · TNA | C27: =2*RATE(Ejercicios!$B$182,Ejercicios!$B$181,-Ejercicios!$B$179,Ejercicios!$B$180) -> 0.095651986 | D27: =2*TASA(6;4;-96;100) | E27: TNA = i semestral × 2 (es la que suelen mostrar las pantallas).
A28: 25 | B28: Trimestral · TEA | C28: =(1+RATE(Ejercicios!$B$190,Ejercicios!$B$189,-Ejercicios!$B$187,Ejercicios!$B$188))^4-1 -> 0.13816708 | D28: =(1+TASA(8;3;-98;100))^4-1 | E28: Tasa trimestral con TASA y después ^4.
A29: 26 | B29: Amortizable · precio | C29: =NPV(Ejercicios!$B$195,Ejercicios!$B$197:$E$197) -> 95.988956 | D29: =VNA(12%;C?:F?) (flujos de los años 1 a 4) | E29: Flujos: 35; 32,5; 30; 27,5 (amortización 25 + interés sobre saldo). VNA descuenta desde el período 1.
A30: 27 | B30: Amortizable · TIR | C30: =IRR(Ejercicios!$B$203:$F$203) -> 0.11482822 | D30: =TIR(B?:F?) | E30: Con el precio negativo en el período 0, TIR resuelve la tasa que iguala el VNA al precio.
A31: 28 | B31: Amortizable semestral · precio | C31: =NPV(Ejercicios!$B$208,Ejercicios!$B$210:$K$210) -> 95.44347 | D31: =VNA(5%;C?:L?) | E31: Flujo del semestre k = 10 + 4% × saldo al inicio: 14; 13,6; 13,2; … ; 10,4.
A32: 29 | B32: Amortizable semestral · TEA | C32: =(1+IRR(Ejercicios!$B$216:$L$216))^2-1 -> 0.10462754 | D32: =(1+TIR(B?:L?))^2-1 | E32: TIR da la tasa semestral; se anualiza con ^2.
A33: 30 | B33: Amortizable con gracia · TIR | C33: =IRR(Ejercicios!$B$222:$F$222) -> 0.11938097 | D33: =TIR(B?:F?) | E33: Flujos: 9; 9; 59; 54,5. Precio bajo la par → TIR > 9%.
A34: 31 | B34: Current yield | C34: =Ejercicios!$B$227/Ejercicios!$B$228 -> 0.086956522 | D34: =8/92 | E34: Current yield = cupón anual / precio. No considera la ganancia hasta la par.
A35: 32 | B35: Current yield | C35: =Ejercicios!$B$234/PV(Ejercicios!$B$236,Ejercicios!$B$235,-Ejercicios!$B$234,-Ejercicios!$B$233) -> 0.10646758 | D35: =100/VA(12%;4;-100;-1000) | E35: Precio 939,25 → 100/939,25 = 10,65% (pregunta del banco).
A36: 33 | B36: Current yield | C36: =2*Ejercicios!$B$241/Ejercicios!$B$242 -> 0.063829787 | D36: =6/94 | E36: Se usa el cupón de todo el año: 2 × 3 = 6.
A37: 34 | B37: Duration Macaulay | C37: =SUMPRODUCT(Ejercicios!$B$248:$D$248,Ejercicios!$B$249:$D$249/(1+Ejercicios!$B$247)^Ejercicios!$B$248:$D$248)/SUMPRODUCT(Ejercicios!$B$249:$D$249/(1+Ejercicios!$B$247)^Ejercicios!$B$248:$D$248) -> 2.7355372 | D37: =SUMAPRODUCTO(t;flujo/(1+10%)^t)/SUMAPRODUCTO(flujo/(1+10%)^t) | E37: D = Σ t × VA(flujo_t) / precio. Da ≈ 2,74 años.
A38: 35 | B38: Duration modificada | C38: =SUMPRODUCT(Ejercicios!$B$255:$D$255,Ejercicios!$B$256:$D$256/(1+Ejercicios!$B$254)^Ejercicios!$B$255:$D$255)/SUMPRODUCT(Ejercicios!$B$256:$D$256/(1+Ejercicios!$B$254)^Ejercicios!$B$255:$D$255)/(1+Ejercicios!$B$254) -> 2.486852 | D38: =Macaulay/(1+10%) | E38: DM = D Macaulay / (1 + TIR).
A39: 36 | B39: Duration modificada | C39: =Ejercicios!$B$261/(1+Ejercicios!$B$262) -> 4.6296296 | D39: =5/(1+8%) | E39: En un cupón cero la Macaulay es el plazo (5); la modificada es 5/1,08.
A40: 37 | B40: Duration Macaulay | C40: =SUMPRODUCT(Ejercicios!$B$268:$F$268,Ejercicios!$B$269:$F$269/(1+Ejercicios!$B$267)^Ejercicios!$B$268:$F$268)/SUMPRODUCT(Ejercicios!$B$269:$F$269/(1+Ejercicios!$B$267)^Ejercicios!$B$268:$F$268) -> 4.2814121 | D40: =SUMAPRODUCTO(t;flujo/(1+10%)^t)/precio | E40: Menor que 5 porque los cupones adelantan flujos.
A41: 38 | B41: Duration amortizable | C41: =SUMPRODUCT(Ejercicios!$B$275:$E$275,Ejercicios!$B$276:$E$276/(1+Ejercicios!$B$274)^Ejercicios!$B$275:$E$275)/SUMPRODUCT(Ejercicios!$B$276:$E$276/(1+Ejercicios!$B$274)^Ejercicios!$B$275:$E$275) -> 2.2610394 | D41: =SUMAPRODUCTO(t;flujo/(1+12%)^t)/precio | E41: Como devuelve capital antes, la duration es mucho menor que 4.
...

Sheet Fórmulas
A1: Qué querés calcular | B1: Excel en español | C1: Ejemplo | D1: Ojo
A2: Precio de un bono con cupón fijo | B2: =VA(tasa; nper; -cupón; -VN) | C2: =VA(10%;5;-8;-100) → 92,42 | D2: Tasa y nper en la misma unidad (años, semestres).
A3: TIR de un bono con cupón fijo | B3: =TASA(nper; cupón; -precio; VN) | C3: =TASA(4;7;-95;100) → 8,53% | D3: Devuelve la tasa del período de los flujos.
A4: TIR de un flujo cualquiera | B4: =TIR(rango de flujos) | C4: =TIR(-950;60;70;80;1100) | D4: El precio va negativo en el período 0.
A5: Precio de un flujo cualquiera | B5: =VNA(tasa; flujos del 1 en adelante) | C5: =VNA(12%;35;32,5;30;27,5) | D5: VNA descuenta desde el período 1: no incluyas el período 0.
A6: TIR con fechas reales | B6: =TIR.NO.PER(flujos; fechas) | C6: =TIR.NO.PER(B10:E10;B9:E9) | D6: Devuelve tasa efectiva anual.
A7: Semestral → efectiva anual | B7: =(1+i)^2-1 | C7: 4% semestral → 8,16% | D7: Trimestral: ^4; mensual: ^12.
A8: Efectiva anual → semestral | B8: =(1+TEA)^(1/2)-1 | C8: 10% → 4,88%
A9: TNA ↔ tasa del período | B9: TNA = i × períodos por año | C9: 4% semestral = 8% TNA | D9: La TNA no capitaliza.
A10: Letra con TNA | B10: =VN/(1+TNA*días/365) | D10: Interés simple.
A11: Current yield | B11: =cupón anual / precio | C11: =8/92 → 8,70%
A12: Duration de Macaulay | B12: =SUMAPRODUCTO(t;flujo/(1+r)^t)/SUMAPRODUCTO(flujo/(1+r)^t) | D12: También existe =DURACION() con fechas.
A13: Duration modificada | B13: = Macaulay / (1 + r) | D13: r en la misma periodicidad de los flujos.
A14: Variación de precio | B14: ΔP/P ≈ −DM × Δy (+ ½ × C × Δy²) | C14: DM 4,5 y +0,5% → −2,25% | D14: Δy en decimal: 0,5% = 0,005.
A15: Valor técnico | B15: = residual + residual × cupón × días/365 | D15: Intereses corridos desde el último pago.
A16: Paridad | B16: = precio / valor técnico | D16: < 100%: bajo la par.
A17: Precio limpio | B17: = sucio − intereses corridos
A19: En Excel en inglés: VA = PV, TASA = RATE, TIR = IRR, VNA = NPV, TIR.NO.PER = XIRR, SUMAPRODUCTO = SUMPRODUCT. Separador de argumentos en español: «;».
