Workbook

Sheet Índice
A1: Bonos y TIR · serie 2 · 50 ejercicios
A2: 20 rápidos con los datos y flujos cargados y 30 completos con solo la consigna, para armar el flujo de fondos desde cero. Cada respuesta se corrige sola.
A3: Hojas: Rápidos · Completos · Soluciones (al final, para mirar después).
A5: N.º | B5: Tipo | C5: Tema | D5: Estado | E5: Ir
A6: 51 | B6: Rápido | C6: Cupón cero · precio | D6: =IF(Rápidos!$D$10="","Pendiente",Rápidos!$D$10) | E6: Ir al ej. 51
A7: 52 | B7: Rápido | C7: Letra · TNA | D7: =IF(Rápidos!$D$18="","Pendiente",Rápidos!$D$18) | E7: Ir al ej. 52
A8: 53 | B8: Rápido | C8: TNA → TEA | D8: =IF(Rápidos!$D$25="","Pendiente",Rápidos!$D$25) | E8: Ir al ej. 53
A9: 54 | B9: Rápido | C9: TEA → TEM | D9: =IF(Rápidos!$D$32="","Pendiente",Rápidos!$D$32) | E9: Ir al ej. 54
A10: 55 | B10: Rápido | C10: Bullet anual · TIR | D10: =IF(Rápidos!$D$39="","Pendiente",Rápidos!$D$39) | E10: Ir al ej. 55
A11: 56 | B11: Rápido | C11: Semestral · TIR → TEA | D11: =IF(Rápidos!$D$46="","Pendiente",Rápidos!$D$46) | E11: Ir al ej. 56
A12: 57 | B12: Rápido | C12: Current yield | D12: =IF(Rápidos!$D$53="","Pendiente",Rápidos!$D$53) | E12: Ir al ej. 57
A13: 58 | B13: Rápido | C13: Paridad | D13: =IF(Rápidos!$D$61="","Pendiente",Rápidos!$D$61) | E13: Ir al ej. 58
A14: 59 | B14: Rápido | C14: Valor técnico | D14: =IF(Rápidos!$D$69="","Pendiente",Rápidos!$D$69) | E14: Ir al ej. 59
A15: 60 | B15: Rápido | C15: Duration con flujos | D15: =IF(Rápidos!$D$77="","Pendiente",Rápidos!$D$77) | E15: Ir al ej. 60
A16: 61 | B16: Rápido | C16: Duration modificada | D16: =IF(Rápidos!$D$85="","Pendiente",Rápidos!$D$85) | E16: Ir al ej. 61
A17: 62 | B17: Rápido | C17: Variación de precio con DM | D17: =IF(Rápidos!$D$92="","Pendiente",Rápidos!$D$92) | E17: Ir al ej. 62
A18: 63 | B18: Rápido | C18: DM + convexidad | D18: =IF(Rápidos!$D$100="","Pendiente",Rápidos!$D$100) | E18: Ir al ej. 63
A19: 64 | B19: Rápido | C19: Precio con flujos | D19: =IF(Rápidos!$D$108="","Pendiente",Rápidos!$D$108) | E19: Ir al ej. 64
A20: 65 | B20: Rápido | C20: PPV con flujos | D20: =IF(Rápidos!$D$115="","Pendiente",Rápidos!$D$115) | E20: Ir al ej. 65
A21: 66 | B21: Rápido | C21: Duration de cartera | D21: =IF(Rápidos!$D$126="","Pendiente",Rápidos!$D$126) | E21: Ir al ej. 66
A22: 67 | B22: Rápido | C22: TIR.NO.PER | D22: =IF(Rápidos!$D$133="","Pendiente",Rápidos!$D$133) | E22: Ir al ej. 67
A23: 68 | B23: Rápido | C23: Monto a invertir | D23: =IF(Rápidos!$D$141="","Pendiente",Rápidos!$D$141) | E23: Ir al ej. 68
A24: 69 | B24: Rápido | C24: Caución | D24: =IF(Rápidos!$D$149="","Pendiente",Rápidos!$D$149) | E24: Ir al ej. 69
A25: 70 | B25: Rápido | C25: TIR nominal → TEA | D25: =IF(Rápidos!$D$156="","Pendiente",Rápidos!$D$156) | E25: Ir al ej. 70
A26: 71 | B26: Completo | C26: Bullet anual · TIR | D26: =IF(Completos!$D$7="","Pendiente",Completos!$D$7) | E26: Ir al ej. 71
A27: 72 | B27: Completo | C27: Bullet semestral · TEA | D27: =IF(Completos!$D$28="","Pendiente",Completos!$D$28) | E27: Ir al ej. 72
A28: 73 | B28: Completo | C28: Bullet semestral · TIR nominal | D28: =IF(Completos!$D$49="","Pendiente",Completos!$D$49) | E28: Ir al ej. 73
A29: 74 | B29: Completo | C29: Amortizable · precio | D29: =IF(Completos!$D$70="","Pendiente",Completos!$D$70) | E29: Ir al ej. 74
A30: 75 | B30: Completo | C30: Amortizable con gracia · TEA | D30: =IF(Completos!$D$91="","Pendiente",Completos!$D$91) | E30: Ir al ej. 75
A31: 76 | B31: Completo | C31: Duration de un bullet | D31: =IF(Completos!$D$112="","Pendiente",Completos!$D$112) | E31: Ir al ej. 76
A32: 77 | B32: Completo | C32: Duration modificada semestral | D32: =IF(Completos!$D$133="","Pendiente",Completos!$D$133) | E32: Ir al ej. 77
A33: 78 | B33: Completo | C33: Convexidad | D33: =IF(Completos!$D$154="","Pendiente",Completos!$D$154) | E33: Ir al ej. 78
A34: 79 | B34: Completo | C34: PPV de un amortizable | D34: =IF(Completos!$D$175="","Pendiente",Completos!$D$175) | E34: Ir al ej. 79
A35: 80 | B35: Completo | C35: Sensibilidad por duration | D35: =IF(Completos!$D$196="","Pendiente",Completos!$D$196) | E35: Ir al ej. 80
A36: 81 | B36: Completo | C36: Sensibilidad con convexidad | D36: =IF(Completos!$D$217="","Pendiente",Completos!$D$217) | E36: Ir al ej. 81
A37: 82 | B37: Completo | C37: Variación real de precio | D37: =IF(Completos!$D$238="","Pendiente",Completos!$D$238) | E37: Ir al ej. 82
A38: 83 | B38: Completo | C38: AL30 · TIR | D38: =IF(Completos!$D$259="","Pendiente",Completos!$D$259) | E38: Ir al ej. 83
A39: 84 | B39: Completo | C39: GD35 · TIR | D39: =IF(Completos!$D$280="","Pendiente",Completos!$D$280) | E39: Ir al ej. 84
A40: 85 | B40: Completo | C40: Precio con fechas | D40: =IF(Completos!$D$301="","Pendiente",Completos!$D$301) | E40: Ir al ej. 85
A41: 86 | B41: Completo | C41: Duration con fechas | D41: =IF(Completos!$D$322="","Pendiente",Completos!$D$322) | E41: Ir al ej. 86
...

Sheet Rápidos
A1: Ejercicios rápidos (51 a 70)
A2: Los datos y los flujos ya están cargados en azul. Resolvelos con fórmulas en la celda amarilla o en el espacio de al lado.
A3: Cómo cargar la respuesta: tasas y variaciones como porcentaje (7,72%), precios, durations y montos como número (92,42).
A5: Ejercicio 51 | B5: Cupón cero · precio
A6: Un bono cupón cero de VN 100 vence dentro de 3 años. La TIR efectiva anual de mercado es 11%. ¿Cuál es su precio?
A7: Valor nominal | B7: 100
A8: Años al vencimiento | B8: 3
A9: TIR efectiva anual | B9: 0.11
A10: Tu respuesta | D10: =IF(B10="","",IF(ABS(B10-Soluciones!$C$5)<=MAX(0.003*ABS(Soluciones!$C$5),0.0001),"✔ Correcto","✘ Revisá"))
A13: Ejercicio 52 | B13: Letra · TNA
A14: Una letra que paga 100 al vencimiento, dentro de 75 días, cotiza a 95,80. ¿Qué TNA (interés simple, base 365) rinde?
A15: Precio | B15: 95.8
A16: Valor al vencimiento | B16: 100
A17: Días | B17: 75
A18: Tu respuesta | D18: =IF(B18="","",IF(ABS(B18-Soluciones!$C$11)<=MAX(0.003*ABS(Soluciones!$C$11),0.0001),"✔ Correcto","✘ Revisá"))
A21: Ejercicio 53 | B21: TNA → TEA
A22: Un plazo fijo paga una TNA de 36% con capitalización cada 30 días. ¿Cuál es la TEA si renovás capital e intereses todo el año?
A23: TNA | B23: 0.36
A24: Días del período | B24: 30
A25: Tu respuesta | D25: =IF(B25="","",IF(ABS(B25-Soluciones!$C$17)<=MAX(0.003*ABS(Soluciones!$C$17),0.0001),"✔ Correcto","✘ Revisá"))
A28: Ejercicio 54 | B28: TEA → TEM
A29: Una inversión rinde una TEA de 45%. ¿Cuál es la tasa efectiva equivalente para 30 días?
A30: TEA | B30: 0.45
A31: Días | B31: 30
A32: Tu respuesta | D32: =IF(B32="","",IF(ABS(B32-Soluciones!$C$23)<=MAX(0.003*ABS(Soluciones!$C$23),0.0001),"✔ Correcto","✘ Revisá"))
A35: Ejercicio 55 | B35: Bullet anual · TIR
A36: Pagás 92 por un bono que te paga 6 por año durante 4 años y devuelve 100 con el último cupón. ¿Cuál es la TIR efectiva anual?
A37: Año | B37: 0 | C37: 1 | D37: 2 | E37: 3 | F37: 4
A38: Flujo | B38: -92 | C38: 6 | D38: 6 | E38: 6 | F38: 106
A39: Tu respuesta | D39: =IF(B39="","",IF(ABS(B39-Soluciones!$C$29)<=MAX(0.003*ABS(Soluciones!$C$29),0.0001),"✔ Correcto","✘ Revisá"))
A42: Ejercicio 56 | B42: Semestral · TIR → TEA
A43: Un bono paga 4 por semestre durante 3 semestres y 104 en el cuarto. Cotiza 97. ¿Cuál es su TIR efectiva anual?
A44: Año | B44: 0 | C44: 1 | D44: 2 | E44: 3 | F44: 4
A45: Flujo | B45: -97 | C45: 4 | D45: 4 | E45: 4 | F45: 104
A46: Tu respuesta | D46: =IF(B46="","",IF(ABS(B46-Soluciones!$C$35)<=MAX(0.003*ABS(Soluciones!$C$35),0.0001),"✔ Correcto","✘ Revisá"))
A49: Ejercicio 57 | B49: Current yield
A50: Un bono paga un cupón anual de 7,5% sobre VN 100 y cotiza a 88. ¿Cuál es su current yield?
A51: Cupón anual (por 100 VN) | B51: 7.5
A52: Precio | B52: 88
A53: Tu respuesta | D53: =IF(B53="","",IF(ABS(B53-Soluciones!$C$41)<=MAX(0.003*ABS(Soluciones!$C$41),0.0001),"✔ Correcto","✘ Revisá"))
...

Sheet Completos
A1: Ejercicios completos (71 a 100)
A2: Solo la consigna. Armá vos el flujo de fondos en el espacio de abajo de cada uno y calculá lo que se pide.
A3: Cómo cargar la respuesta: tasas y variaciones como porcentaje (7,72%), precios, durations y montos como número (92,42).
A5: Ejercicio 71 | B5: Bullet anual · TIR
A6: Un bono de VN 100 vence dentro de 4 años, paga un cupón de 7% anual al final de cada año y devuelve todo el capital al vencimiento. Cotiza a 96,50. Calculá su TIR efectiva anual.
A7: Tu respuesta | D7: =IF(B7="","",IF(ABS(B7-Soluciones!$C$125)<=MAX(0.003*ABS(Soluciones!$C$125),0.0001),"✔ Correcto","✘ Revisá"))
A8: Tu espacio de trabajo
A26: Ejercicio 72 | B26: Bullet semestral · TEA
A27: Una obligación negociable de VN 100 vence dentro de 3 años, paga un cupón de 9% nominal anual en pagos semestrales y amortiza todo al vencimiento. Cotiza a 101,20. Calculá su TIR efectiva anual.
A28: Tu respuesta | D28: =IF(B28="","",IF(ABS(B28-Soluciones!$C$145)<=MAX(0.003*ABS(Soluciones!$C$145),0.0001),"✔ Correcto","✘ Revisá"))
A29: Tu espacio de trabajo
A47: Ejercicio 73 | B47: Bullet semestral · TIR nominal
A48: Un bono de VN 100 vence dentro de 5 años, paga un cupón de 6% nominal anual en pagos semestrales y amortiza todo al vencimiento. Cotiza a 94. Calculá su TIR expresada como tasa nominal anual capitalizable semestralmente.
A49: Tu respuesta | D49: =IF(B49="","",IF(ABS(B49-Soluciones!$C$167)<=MAX(0.003*ABS(Soluciones!$C$167),0.0001),"✔ Correcto","✘ Revisá"))
A50: Tu espacio de trabajo
A68: Ejercicio 74 | B68: Amortizable · precio
A69: Un bono de VN 100 amortiza 25% del capital al final de cada uno de los próximos 4 años y paga un cupón de 8% anual sobre el saldo pendiente al inicio de cada año. ¿Cuánto vale si la TIR efectiva anual de mercado es 10%?
A70: Tu respuesta | D70: =IF(B70="","",IF(ABS(B70-Soluciones!$C$193)<=MAX(0.003*ABS(Soluciones!$C$193),0.0001),"✔ Correcto","✘ Revisá"))
A71: Tu espacio de trabajo
A89: Ejercicio 75 | B89: Amortizable con gracia · TEA
A90: Un bono de VN 100 vence dentro de 5 años. Paga cupón de 5% nominal anual en pagos semestrales sobre el saldo. Amortiza en 5 cuotas semestrales iguales, la primera a los 3 años (semestre 6) y la última al vencimiento. Cotiza a 88. Calculá su TIR efectiva anual.
A91: Tu respuesta | D91: =IF(B91="","",IF(ABS(B91-Soluciones!$C$213)<=MAX(0.003*ABS(Soluciones!$C$213),0.0001),"✔ Correcto","✘ Revisá"))
A92: Tu espacio de trabajo
A110: Ejercicio 76 | B110: Duration de un bullet
A111: Un bono de VN 100 vence dentro de 5 años, paga un cupón de 6% anual al final de cada año y amortiza todo al vencimiento. Con una TIR efectiva anual de 8%, calculá su duration (Macaulay, en años).
A112: Tu respuesta | D112: =IF(B112="","",IF(ABS(B112-Soluciones!$C$239)<=MAX(0.003*ABS(Soluciones!$C$239),0.0001),"✔ Correcto","✘ Revisá"))
A113: Tu espacio de trabajo
A131: Ejercicio 77 | B131: Duration modificada semestral
A132: Un bono de VN 100 vence dentro de 3 años, paga un cupón de 10% nominal anual en pagos semestrales y amortiza todo al vencimiento. Su TIR es 12% nominal anual capitalizable semestralmente. Calculá su duration modificada.
A133: Tu respuesta | D133: =IF(B133="","",IF(ABS(B133-Soluciones!$C$260)<=MAX(0.003*ABS(Soluciones!$C$260),0.0001),"✔ Correcto","✘ Revisá"))
A134: Tu espacio de trabajo
A152: Ejercicio 78 | B152: Convexidad
A153: Un bono de VN 100 vence dentro de 4 años, paga un cupón de 5% anual al final de cada año y amortiza todo al vencimiento. Con una TIR efectiva anual de 9%, calculá su convexidad.
A154: Tu respuesta | D154: =IF(B154="","",IF(ABS(B154-Soluciones!$C$282)<=MAX(0.003*ABS(Soluciones!$C$282),0.0001),"✔ Correcto","✘ Revisá"))
A155: Tu espacio de trabajo
A173: Ejercicio 79 | B173: PPV de un amortizable
A174: Un bono de VN 100 vence dentro de 6 años, paga un cupón de 6% anual sobre saldo al final de cada año y amortiza en 3 cuotas anuales iguales en los años 4, 5 y 6. Calculá su promedio ponderado de vida (PPV) según la fórmula del apunte.
A175: Tu respuesta | D175: =IF(B175="","",IF(ABS(B175-Soluciones!$C$302)<=MAX(0.003*ABS(Soluciones!$C$302),0.0001),"✔ Correcto","✘ Revisá"))
A176: Tu espacio de trabajo
A194: Ejercicio 80 | B194: Sensibilidad por duration
...

Sheet Soluciones
A1: Soluciones · serie 2
A2: Mirala después de resolver. En los completos está el flujo de fondos armado, con fórmulas vivas.
A4: Ejercicio 51 | B4: Rápido · Cupón cero · precio
A5: Respuesta | C5: 73.119138 | D5: 73,12
A6: En Excel | C6: =100/(1+11%)^3 ó =VA(11%;3;0;-100)
A7: Explicación | C7: El único flujo (100) se descuenta 3 años a la TIR: P = 100 / 1,11³.
A10: Ejercicio 52 | B10: Rápido · Letra · TNA
A11: Respuesta | C11: 0.21336117 | D11: 21,34 %
A12: En Excel | C12: =(100/95,8-1)*365/75
A13: Explicación | C13: Rendimiento directo del plazo (100/95,80 − 1) llevado a año en forma proporcional: × 365/75.
A16: Ejercicio 53 | B16: Rápido · TNA → TEA
A17: Respuesta | C17: 0.4258623 | D17: 42,59 %
A18: En Excel | C18: =(1+36%*30/365)^(365/30)-1
A19: Explicación | C19: Tasa del período = TNA × 30/365; se capitaliza 365/30 veces en el año.
A22: Ejercicio 54 | B22: Rápido · TEA → TEM
A23: Respuesta | C23: 0.031010584 | D23: 3,10 %
A24: En Excel | C24: =(1+45%)^(30/365)-1
A25: Explicación | C25: Las tasas efectivas se convierten con potencias: (1 + TEA)^(30/365) − 1.
A28: Ejercicio 55 | B28: Rápido · Bullet anual · TIR
A29: Respuesta | C29: 0.084390116 | D29: 8,44 %
A30: En Excel | C30: =TIR(flujos)
A31: Explicación | C31: Con pagos anuales, la TIR de los flujos ya es efectiva anual.
A34: Ejercicio 56 | B34: Rápido · Semestral · TIR → TEA
A35: Respuesta | C35: 0.099204442 | D35: 9,92 %
A36: En Excel | C36: =(1+TIR(flujos))^2-1
A37: Explicación | C37: TIR(flujos) da la tasa semestral; se pasa a efectiva anual elevando al cuadrado.
A40: Ejercicio 57 | B40: Rápido · Current yield
A41: Respuesta | C41: 0.085227273 | D41: 8,52 %
A42: En Excel | C42: =7,5/88
A43: Explicación | C43: CY = renta anual / precio.
A46: Ejercicio 58 | B46: Rápido · Paridad
A47: Respuesta | C47: 0.90522876 | D47: 90,52 %
A48: En Excel | C48: =55,4/(60+1,2)
A49: Explicación | C49: Paridad = precio / valor técnico, con VT = VR + intereses corridos.
A52: Ejercicio 59 | B52: Rápido · Valor técnico
A53: Respuesta | C53: 80.96 | D53: 80,96
A54: En Excel | C54: =80+80*6%*73/365
A55: Explicación | C55: VT = VR + VR × cupón × días/365.
A58: Ejercicio 60 | B58: Rápido · Duration con flujos
A59: Respuesta | C59: 3.5616942 | D59: 3,562
...
